Workbook

Sheet README
B2: Leather Chemicals Stock System — 2026-27
B3: Rebuilt from your original 2026-27_Stock.xlsx (one column per chemical, purchases and sales mixed into a wide block per quarter sheet) into the same analysis-ready tidy tables as your other stock workbooks.
B5: Source file: 2026-27_Stock.xlsx — sheets '1sr qtr 26-27' and '2nd qtr 26-27'
B7: How this workbook is organised
B8: 1. Product_Master — one row per chemical (55 products): Opening Stock is the 'Stock as 01.04.2026' figure from the source (start of FY26-27), Packing Size, and the latest Purchase & Sale rate found in the source. These are your INPUT cells (blue text) — edit rates here, everything downstream updates.
B10: 2. Transactions — every purchase, sale and adjustment line from both quarter sheets (601 rows: 524 from Q1 26-27 + 77 from Q2 26-27), formatted as an Excel Table. Q2 26-27 only runs through 16 Jul 2026, matching how far your source sheet had been filled in when this file was generated — keep adding new rows at the bottom as you buy/sell.
B12: 3. Stock_Summary — one row per product, fully formula-driven (SUMIFS off the Transactions table): Opening + Purchases − Sales − Adjustments = Closing Stock, plus stock value & sales value, across the whole file.
B14: 4. Dashboard — KPI cards pulled live from Stock_Summary.
B16: Data-quality notes (source data reproduced as-is, not corrected)
B17: • Each source sheet ended with a single 'Adj' line carrying a net correction per product (11 products in Q1 26-27, none yet recorded in Q2 26-27). These are kept as Type = Adjustment transactions, undated, exactly as entered in the source. Every product's Opening + Purchases − Sales − Adjustments reconciles exactly to the 'Stock as on <date>' figure printed in the source sheet — the conversion was verified line by line.
B18: • A handful of source rows had no date filled in (15 rows) — these are kept with a blank Date, exactly as in the source.
B19: • Six Q2 26-27 sale rows are dated '09.07.29' in the source (likely a typo for '09.07.26') — reproduced as written; you may want to correct the year at source.
... B32: Charts added: on the Analysis sheet — a Pareto chart (Sales Value + Cumulative %) and a Turnover-vs-Margin scatter and a Closing-Stock-vs-Sales bar for products (next to Section 1); a Top-15-customers bar and a Top-5-vs-Others donut (next to Section 2). On the Dashboard — a Low Stock Alerts table and chart showing shortfall vs Reorder Level (fill in Reorder Level in Product_Master to activate it).

Sheet Dashboard
B2: Leather Chemicals Stock System — 2026-27
B4: Total Stock Value (Rs) | D4: Total Sales Value (Rs) | F4: Total Closing Stock (kg) | H4: Products Low on Stock
B5: =Stock_Summary!K57 -> 8721679 | D5: =Stock_Summary!L57 -> 13028164 | F5: =Stock_Summary!F57 -> 72743 | H5: =COUNTIF(Stock_Summary!N2:N56,"LOW STOCK") -> 0
B52: Low Stock Alerts
B53: Shows how far each product is below its Reorder Level (Product_Master). Currently blank until you fill in Reorder Levels — the table & chart activate automatically once you do.
L54: Product | M54: Shortfall (kg) | N54: Rank
B55: Rank | C55: Product | D55: Reorder Level (kg) | E55: Closing Stock (kg) | F55: Shortfall (kg) | L55: =Stock_Summary!A2 -> KG | M55: =MAX(Stock_Summary!M2-Stock_Summary!F2,0) -> 0 | N55: =RANK(M55,$M$55:$M$109,0)+COUNTIF($M$55:M55,M55)-1 -> 1
B56: 1 | C56: =IFERROR(INDEX($L$55:$L$109,MATCH(B56,$N$55:$N$109,0)),"") -> KG | D56: =IFERROR(INDEX(Stock_Summary!$M$2:$M$56,MATCH(C56,Stock_Summary!$A$2:$A$56,0)),"") -> 0 | E56: =IFERROR(INDEX(Stock_Summary!$F$2:$F$56,MATCH(C56,Stock_Summary!$A$2:$A$56,0)),"") -> 3020 | F56: =IFERROR(INDEX($M$55:$M$109,MATCH(B56,$N$55:$N$109,0)),"") -> 0 | L56: =Stock_Summary!A3 -> AA | M56: =MAX(Stock_Summary!M3-Stock_Summary!F3,0) -> 0 | N56: =RANK(M56,$M$55:$M$109,0)+COUNTIF($M$55:M56,M56)-1 -> 2
B57: 2 | C57: =IFERROR(INDEX($L$55:$L$109,MATCH(B57,$N$55:$N$109,0)),"") -> AA | D57: =IFERROR(INDEX(Stock_Summary!$M$2:$M$56,MATCH(C57,Stock_Summary!$A$2:$A$56,0)),"") -> 0 | E57: =IFERROR(INDEX(Stock_Summary!$F$2:$F$56,MATCH(C57,Stock_Summary!$A$2:$A$56,0)),"") -> 3233 | F57: =IFERROR(INDEX($M$55:$M$109,MATCH(B57,$N$55:$N$109,0)),"") -> 0 | L57: =Stock_Summary!A4 -> WAK | M57: =MAX(Stock_Summary!M4-Stock_Summary!F4,0) -> 0 | N57: =RANK(M57,$M$55:$M$109,0)+COUNTIF($M$55:M57,M57)-1 -> 3
B58: 3 | C58: =IFERROR(INDEX($L$55:$L$109,MATCH(B58,$N$55:$N$109,0)),"") -> WAK | D58: =IFERROR(INDEX(Stock_Summary!$M$2:$M$56,MATCH(C58,Stock_Summary!$A$2:$A$56,0)),"") -> 0 | E58: =IFERROR(INDEX(Stock_Summary!$F$2:$F$56,MATCH(C58,Stock_Summary!$A$2:$A$56,0)),"") -> 5461 | F58: =IFERROR(INDEX($M$55:$M$109,MATCH(B58,$N$55:$N$109,0)),"") -> 0 | L58: =Stock_Summary!A5 -> SNA | M58: =MAX(Stock_Summary!M5-Stock_Summary!F5,0) -> 0 | N58: =RANK(M58,$M$55:$M$109,0)+COUNTIF($M$55:M58,M58)-1 -> 4
B59: 4 | C59: =IFERROR(INDEX($L$55:$L$109,MATCH(B59,$N$55:$N$109,0)),"") -> SNA | D59: =IFERROR(INDEX(Stock_Summary!$M$2:$M$56,MATCH(C59,Stock_Summary!$A$2:$A$56,0)),"") -> 0 | E59: =IFERROR(INDEX(Stock_Summary!$F$2:$F$56,MATCH(C59,Stock_Summary!$A$2:$A$56,0)),"") -> 8211 | F59: =IFERROR(INDEX($M$55:$M$109,MATCH(B59,$N$55:$N$109,0)),"") -> 0 | L59: =Stock_Summary!A6 -> SBL | M59: =MAX(Stock_Summary!M6-Stock_Summary!F6,0) -> 0 | N59: =RANK(M59,$M$55:$M$109,0)+COUNTIF($M$55:M59,M59)-1 -> 5
B60: 5 | C60: =IFERROR(INDEX($L$55:$L$109,MATCH(B60,$N$55:$N$109,0)),"") -> SBL | D60: =IFERROR(INDEX(Stock_Summary!$M$2:$M$56,MATCH(C60,Stock_Summary!$A$2:$A$56,0)),"") -> 0 | E60: =IFERROR(INDEX(Stock_Summary!$F$2:$F$56,MATCH(C60,Stock_Summary!$A$2:$A$56,0)),"") -> 9000 | F60: =IFERROR(INDEX($M$55:$M$109,MATCH(B60,$N$55:$N$109,0)),"") -> 0 | L60: =Stock_Summary!A7 -> XAC | M60: =MAX(Stock_Summary!M7-Stock_Summary!F7,0) -> 0 | N60: =RANK(M60,$M$55:$M$109,0)+COUNTIF($M$55:M60,M60)-1 -> 6
B61: 6 | C61: =IFERROR(INDEX($L$55:$L$109,MATCH(B61,$N$55:$N$109,0)),"") -> XAC | D61: =IFERROR(INDEX(Stock_Summary!$M$2:$M$56,MATCH(C61,Stock_Summary!$A$2:$A$56,0)),"") -> 0 | E61: =IFERROR(INDEX(Stock_Summary!$F$2:$F$56,MATCH(C61,Stock_Summary!$A$2:$A$56,0)),"") -> 1542 | F61: =IFERROR(INDEX($M$55:$M$109,MATCH(B61,$N$55:$N$109,0)),"") -> 0 | L61: =Stock_Summary!A8 -> WFAT | M61: =MAX(Stock_Summary!M8-Stock_Summary!F8,0) -> 0 | N61: =RANK(M61,$M$55:$M$109,0)+COUNTIF($M$55:M61,M61)-1 -> 7
B62: 7 | C62: =IFERROR(INDEX($L$55:$L$109,MATCH(B62,$N$55:$N$109,0)),"") -> WFAT | D62: =IFERROR(INDEX(Stock_Summary!$M$2:$M$56,MATCH(C62,Stock_Summary!$A$2:$A$56,0)),"") -> 0 | E62: =IFERROR(INDEX(Stock_Summary!$F$2:$F$56,MATCH(C62,Stock_Summary!$A$2:$A$56,0)),"") -> 328 | F62: =IFERROR(INDEX($M$55:$M$109,MATCH(B62,$N$55:$N$109,0)),"") -> 0 | L62: =Stock_Summary!A9 -> SUL | M62: =MAX(Stock_Summary!M9-Stock_Summary!F9,0) -> 0 | N62: =RANK(M62,$M$55:$M$109,0)+COUNTIF($M$55:M62,M62)-1 -> 8
B63: 8 | C63: =IFERROR(INDEX($L$55:$L$109,MATCH(B63,$N$55:$N$109,0)),"") -> SUL | D63: =IFERROR(INDEX(Stock_Summary!$M$2:$M$56,MATCH(C63,Stock_Summary!$A$2:$A$56,0)),"") -> 0 | E63: =IFERROR(INDEX(Stock_Summary!$F$2:$F$56,MATCH(C63,Stock_Summary!$A$2:$A$56,0)),"") -> 5768 | F63: =IFERROR(INDEX($M$55:$M$109,MATCH(B63,$N$55:$N$109,0)),"") -> 0 | L63: =Stock_Summary!A10 -> KR | M63: =MAX(Stock_Summary!M10-Stock_Summary!F10,0) -> 0 | N63: =RANK(M63,$M$55:$M$109,0)+COUNTIF($M$55:M63,M63)-1 -> 9
B64: 9 | C64: =IFERROR(INDEX($L$55:$L$109,MATCH(B64,$N$55:$N$109,0)),"") -> KR | D64: =IFERROR(INDEX(Stock_Summary!$M$2:$M$56,MATCH(C64,Stock_Summary!$A$2:$A$56,0)),"") -> 0 | E64: =IFERROR(INDEX(Stock_Summary!$F$2:$F$56,MATCH(C64,Stock_Summary!$A$2:$A$56,0)),"") -> 32 | F64: =IFERROR(INDEX($M$55:$M$109,MATCH(B64,$N$55:$N$109,0)),"") -> 0 | L64: =Stock_Summary!A11 -> G1 | M64: =MAX(Stock_Summary!M11-Stock_Summary!F11,0) -> 0 | N64: =RANK(M64,$M$55:$M$109,0)+COUNTIF($M$55:M64,M64)-1 -> 10
B65: 10 | C65: =IFERROR(INDEX($L$55:$L$109,MATCH(B65,$N$55:$N$109,0)),"") -> G1 | D65: =IFERROR(INDEX(Stock_Summary!$M$2:$M$56,MATCH(C65,Stock_Summary!$A$2:$A$56,0)),"") -> 0 | E65: =IFERROR(INDEX(Stock_Summary!$F$2:$F$56,MATCH(C65,Stock_Summary!$A$2:$A$56,0)),"") -> 500 | F65: =IFERROR(INDEX($M$55:$M$109,MATCH(B65,$N$55:$N$109,0)),"") -> 0 | L65: =Stock_Summary!A12 -> G2 | M65: =MAX(Stock_Summary!M12-Stock_Summary!F12,0) -> 0 | N65: =RANK(M65,$M$55:$M$109,0)+COUNTIF($M$55:M65,M65)-1 -> 11
L66: =Stock_Summary!A13 -> Silcoat | M66: =MAX(Stock_Summary!M13-Stock_Summary!F13,0) -> 0 | N66: =RANK(M66,$M$55:$M$109,0)+COUNTIF($M$55:M66,M66)-1 -> 12
L67: =Stock_Summary!A14 -> TiO2 | M67: =MAX(Stock_Summary!M14-Stock_Summary!F14,0) -> 0 | N67: =RANK(M67,$M$55:$M$109,0)+COUNTIF($M$55:M67,M67)-1 -> 13
L68: =Stock_Summary!A15 -> TiO2 R | M68: =MAX(Stock_Summary!M15-Stock_Summary!F15,0) -> 0 | N68: =RANK(M68,$M$55:$M$109,0)+COUNTIF($M$55:M68,M68)-1 -> 14
L69: =Stock_Summary!A16 -> ZnO | M69: =MAX(Stock_Summary!M16-Stock_Summary!F16,0) -> 0 | N69: =RANK(M69,$M$55:$M$109,0)+COUNTIF($M$55:M69,M69)-1 -> 15
L70: =Stock_Summary!A17 -> CRTI | M70: =MAX(Stock_Summary!M17-Stock_Summary!F17,0) -> 0 | N70: =RANK(M70,$M$55:$M$109,0)+COUNTIF($M$55:M70,M70)-1 -> 16
L71: =Stock_Summary!A18 -> ACT.A | M71: =MAX(Stock_Summary!M18-Stock_Summary!F18,0) -> 0 | N71: =RANK(M71,$M$55:$M$109,0)+COUNTIF($M$55:M71,M71)-1 -> 17
L72: =Stock_Summary!A19 -> Act. Conc | M72: =MAX(Stock_Summary!M19-Stock_Summary!F19,0) -> 0 | N72: =RANK(M72,$M$55:$M$109,0)+COUNTIF($M$55:M72,M72)-1 -> 18
L73: =Stock_Summary!A20 -> DB | M73: =MAX(Stock_Summary!M20-Stock_Summary!F20,0) -> 0 | N73: =RANK(M73,$M$55:$M$109,0)+COUNTIF($M$55:M73,M73)-1 -> 19
L74: =Stock_Summary!A21 -> RM | M74: =MAX(Stock_Summary!M21-Stock_Summary!F21,0) -> 0 | N74: =RANK(M74,$M$55:$M$109,0)+COUNTIF($M$55:M74,M74)-1 -> 20
L75: =Stock_Summary!A22 -> AW | M75: =MAX(Stock_Summary!M22-Stock_Summary!F22,0) -> 0 | N75: =RANK(M75,$M$55:$M$109,0)+COUNTIF($M$55:M75,M75)-1 -> 21
L76: =Stock_Summary!A23 -> NSA | M76: =MAX(Stock_Summary!M23-Stock_Summary!F23,0) -> 0 | N76: =RANK(M76,$M$55:$M$109,0)+COUNTIF($M$55:M76,M76)-1 -> 22
L77: =Stock_Summary!A24 -> RU | M77: =MAX(Stock_Summary!M24-Stock_Summary!F24,0) -> 0 | N77: =RANK(M77,$M$55:$M$109,0)+COUNTIF($M$55:M77,M77)-1 -> 23
... L109: =Stock_Summary!A56 -> CWET | M109: =MAX(Stock_Summary!M56-Stock_Summary!F56,0) -> 0 | N109: =RANK(M109,$M$55:$M$109,0)+COUNTIF($M$55:M109,M109)-1 -> 55

Sheet Product_Master
A1: Product Code | B1: Category | C1: Opening Stock (kg) | D1: Packing Size (kg/drum) | E1: Purchase Rate (Rs/kg) | F1: Sale Rate (Rs/kg) | G1: Reorder Level (kg)
A2: KG | C2: 1980 | D2: 110 | E2: 93 | F2: 93
A3: AA | C3: 973 | D3: 120 | E3: 96 | F3: 106
A4: WAK | C4: 4713 | D4: 120 | E4: 94 | F4: 102
A5: SNA | C5: 6707 | D5: 120 | E5: 97 | F5: 111
A6: SBL | C6: 4800 | D6: 120 | E6: 99 | F6: 112
A7: XAC | C7: 310 | D7: 120 | E7: 135 | F7: 160
A8: WFAT | C8: 156 | D8: 120 | E8: 130 | F8: 135
A9: SUL | C9: 8978 | D9: 150 | E9: 148 | F9: 185
A10: KR | C10: 512 | D10: 120 | E10: 163 | F10: 175
A11: G1 | C11: 500 | D11: 100 | E11: 105 | F11: 135
A12: G2 | C12: 100 | D12: 100 | E12: 95 | F12: 130
A13: Silcoat | C13: 590 | D13: 60 | E13: 45 | F13: 122
... A33: SUM | C33: 96 | D33: 120 | E33: 67 | F33: 125
A34: DLPS | C34: 0 | E34: 380 | F34: 460
A35: ITS | C35: 0 | D35: 110 | E35: 210 | F35: 278
A36: ACT E | C36: 2131 | D36: 120 | E36: 74 | F36: 102
A37: SBAI | C37: 674 | D37: 25 | E37: 115 | F37: 140
A38: FI | C38: 945 | D38: 25 | E38: 140 | F38: 160
A39: C5I | C39: 108 | D39: 20 | E39: 600 | F39: 900
A40: ALFI | C40: 25 | D40: 25 | E40: 130 | F40: 196
A41: DCD | C41: 18 | D41: 25 | E41: 120 | F41: 140
A42: AM | C42: 15 | D42: 25 | E42: 115 | F42: 125
A43: NHI | C43: 150 | D43: 25 | E43: 100 | F43: 120
A44: NSCI | C44: 360 | D44: 120 | E44: 165 | F44: 221
A45: LA | C45: 210 | D45: 25 | E45: 120 | F45: 150
A46: FCTI | C46: 50 | D46: 25 | E46: 130 | F46: 145
... A56: CWET | C56: 991 | D56: 50 | E56: 45 | F56: 245
C58: =SUM(C2:C57) -> 66590.3

Sheet Transactions
A1: Txn ID | B1: Date | C1: Period | D1: Type | E1: Invoice No | F1: Party | G1: Product | H1: Qty (kg) | I1: Est. Value (Rs)
A2: 1 | B2: 46113 | C2: Q1 26-27 | D2: Sale | E2: 1 | F2: S H W D Enterprise | G2: RM | H2: 75 | I2: =IFERROR(IF(D2="Sale",H2*VLOOKUP(G2,Product_Master!$A:$F,6,FALSE()),IF(D2="Purchase",H2*VLOOKUP(G2,Product_Master!$A:$F,5,FALSE()),0)),0) -> 9450
A3: 2 | B3: 46113 | C3: Q1 26-27 | D3: Sale | E3: 1 | F3: S H W D Enterprise | G3: FI | H3: 75 | I3: =IFERROR(IF(D3="Sale",H3*VLOOKUP(G3,Product_Master!$A:$F,6,FALSE()),IF(D3="Purchase",H3*VLOOKUP(G3,Product_Master!$A:$F,5,FALSE()),0)),0) -> 12000
A4: 3 | B4: 46113 | C4: Q1 26-27 | D4: Sale | E4: 1 | F4: S H W D Enterprise | G4: NHI | H4: 75 | I4: =IFERROR(IF(D4="Sale",H4*VLOOKUP(G4,Product_Master!$A:$F,6,FALSE()),IF(D4="Purchase",H4*VLOOKUP(G4,Product_Master!$A:$F,5,FALSE()),0)),0) -> 9000
A5: 4 | B5: 46113 | C5: Q1 26-27 | D5: Sale | E5: 2 | F5: Taifa Internatioal | G5: SBL | H5: 720 | I5: =IFERROR(IF(D5="Sale",H5*VLOOKUP(G5,Product_Master!$A:$F,6,FALSE()),IF(D5="Purchase",H5*VLOOKUP(G5,Product_Master!$A:$F,5,FALSE()),0)),0) -> 80640
A6: 5 | B6: 46113 | C6: Q1 26-27 | D6: Sale | E6: 2 | F6: Taifa Internatioal | G6: SBAI | H6: 200 | I6: =IFERROR(IF(D6="Sale",H6*VLOOKUP(G6,Product_Master!$A:$F,6,FALSE()),IF(D6="Purchase",H6*VLOOKUP(G6,Product_Master!$A:$F,5,FALSE()),0)),0) -> 28000
A7: 6 | B7: 46113 | C7: Q1 26-27 | D7: Sale | E7: 3 | F7: Taifa Internatioal | G7: SBL | H7: 720 | I7: =IFERROR(IF(D7="Sale",H7*VLOOKUP(G7,Product_Master!$A:$F,6,FALSE()),IF(D7="Purchase",H7*VLOOKUP(G7,Product_Master!$A:$F,5,FALSE()),0)),0) -> 80640
A8: 7 | B8: 46113 | C8: Q1 26-27 | D8: Sale | E8: 3 | F8: Taifa Internatioal | G8: SBAI | H8: 200 | I8: =IFERROR(IF(D8="Sale",H8*VLOOKUP(G8,Product_Master!$A:$F,6,FALSE()),IF(D8="Purchase",H8*VLOOKUP(G8,Product_Master!$A:$F,5,FALSE()),0)),0) -> 28000
A9: 8 | B9: 46113 | C9: Q1 26-27 | D9: Sale | E9: 4 | F9: N N Enterprise | G9: DB | H9: 5 | I9: =IFERROR(IF(D9="Sale",H9*VLOOKUP(G9,Product_Master!$A:$F,6,FALSE()),IF(D9="Purchase",H9*VLOOKUP(G9,Product_Master!$A:$F,5,FALSE()),0)),0) -> 515
A10: 9 | B10: 46113 | C10: Q1 26-27 | D10: Sale | E10: 5 | F10: Dilshad Ahmed & Co | G10: WAK | H10: 720 | I10: =IFERROR(IF(D10="Sale",H10*VLOOKUP(G10,Product_Master!$A:$F,6,FALSE()),IF(D10="Purchase",H10*VLOOKUP(G10,Product_Master!$A:$F,5,FALSE()),0)),0) -> 73440
A11: 10 | B11: 46113 | C11: Q1 26-27 | D11: Sale | E11: 5 | F11: Dilshad Ahmed & Co | G11: SNA | H11: 720 | I11: =IFERROR(IF(D11="Sale",H11*VLOOKUP(G11,Product_Master!$A:$F,6,FALSE()),IF(D11="Purchase",H11*VLOOKUP(G11,Product_Master!$A:$F,5,FALSE()),0)),0) -> 79920
A12: 11 | B12: 46113 | C12: Q1 26-27 | D12: Sale | E12: 5 | F12: Dilshad Ahmed & Co | G12: DB | H12: 360 | I12: =IFERROR(IF(D12="Sale",H12*VLOOKUP(G12,Product_Master!$A:$F,6,FALSE()),IF(D12="Purchase",H12*VLOOKUP(G12,Product_Master!$A:$F,5,FALSE()),0)),0) -> 37080
A13: 12 | B13: 46113 | C13: Q1 26-27 | D13: Sale | E13: 6 | F13: R P Enterprise | G13: SNA | H13: 120 | I13: =IFERROR(IF(D13="Sale",H13*VLOOKUP(G13,Product_Master!$A:$F,6,FALSE()),IF(D13="Purchase",H13*VLOOKUP(G13,Product_Master!$A:$F,5,FALSE()),0)),0) -> 13320
... A23: 22 | B23: 46113 | C23: Q1 26-27 | D23: Sale | E23: 72 | F23: A H Enterprise | G23: XAC | H23: 120 | I23: =IFERROR(IF(D23="Sale",H23*VLOOKUP(G23,Product_Master!$A:$F,6,FALSE()),IF(D23="Purchase",H23*VLOOKUP(G23,Product_Master!$A:$F,5,FALSE()),0)),0) -> 19200
A24: 23 | B24: 46114 | C24: Q1 26-27 | D24: Purchase | F24: CLM | G24: WFAT | H24: 2160 | I24: =IFERROR(IF(D24="Sale",H24*VLOOKUP(G24,Product_Master!$A:$F,6,FALSE()),IF(D24="Purchase",H24*VLOOKUP(G24,Product_Master!$A:$F,5,FALSE()),0)),0) -> 280800
A25: 24 | B25: 46114 | C25: Q1 26-27 | D25: Sale | E25: 9 | F25: Raju Brothers | G25: SBL | H25: 120 | I25: =IFERROR(IF(D25="Sale",H25*VLOOKUP(G25,Product_Master!$A:$F,6,FALSE()),IF(D25="Purchase",H25*VLOOKUP(G25,Product_Master!$A:$F,5,FALSE()),0)),0) -> 13440
A26: 25 | B26: 46114 | C26: Q1 26-27 | D26: Sale | E26: 10 | F26: Integrated Supply Chain | G26: AA | H26: 480 | I26: =IFERROR(IF(D26="Sale",H26*VLOOKUP(G26,Product_Master!$A:$F,6,FALSE()),IF(D26="Purchase",H26*VLOOKUP(G26,Product_Master!$A:$F,5,FALSE()),0)),0) -> 50880
A27: 26 | B27: 46114 | C27: Q1 26-27 | D27: Sale | E27: 11 | F27: Aaqib Tannery | G27: SNA | H27: 240 | I27: =IFERROR(IF(D27="Sale",H27*VLOOKUP(G27,Product_Master!$A:$F,6,FALSE()),IF(D27="Purchase",H27*VLOOKUP(G27,Product_Master!$A:$F,5,FALSE()),0)),0) -> 26640
A28: 27 | B28: 46114 | C28: Q1 26-27 | D28: Sale | E28: 12 | F28: Z K Leather Products | G28: WAK | H28: 480 | I28: =IFERROR(IF(D28="Sale",H28*VLOOKUP(G28,Product_Master!$A:$F,6,FALSE()),IF(D28="Purchase",H28*VLOOKUP(G28,Product_Master!$A:$F,5,FALSE()),0)),0) -> 48960
A29: 28 | B29: 46114 | C29: Q1 26-27 | D29: Sale | E29: 12 | F29: Z K Leather Products | G29: SNA | H29: 480 | I29: =IFERROR(IF(D29="Sale",H29*VLOOKUP(G29,Product_Master!$A:$F,6,FALSE()),IF(D29="Purchase",H29*VLOOKUP(G29,Product_Master!$A:$F,5,FALSE()),0)),0) -> 53280
A30: 29 | B30: 46114 | C30: Q1 26-27 | D30: Sale | E30: 13 | F30: UZAIR ENTERPRISE | G30: KG | H30: 220 | I30: =IFERROR(IF(D30="Sale",H30*VLOOKUP(G30,Product_Master!$A:$F,6,FALSE()),IF(D30="Purchase",H30*VLOOKUP(G30,Product_Master!$A:$F,5,FALSE()),0)),0) -> 20460
A31: 30 | B31: 46114 | C31: Q1 26-27 | D31: Sale | E31: 14 | F31: Skyscrapers Chemex Pvt. Ltd | G31: ACT.A | H31: 50 | I31: =IFERROR(IF(D31="Sale",H31*VLOOKUP(G31,Product_Master!$A:$F,6,FALSE()),IF(D31="Purchase",H31*VLOOKUP(G31,Product_Master!$A:$F,5,FALSE()),0)),0) -> 7750
A32: 31 | B32: 46114 | C32: Q1 26-27 | D32: Sale | E32: 15 | F32: A A Traders | G32: SNA | H32: 120 | I32: =IFERROR(IF(D32="Sale",H32*VLOOKUP(G32,Product_Master!$A:$F,6,FALSE()),IF(D32="Purchase",H32*VLOOKUP(G32,Product_Master!$A:$F,5,FALSE()),0)),0) -> 13320
A33: 32 | B33: 46114 | C33: Q1 26-27 | D33: Sale | E33: 15 | F33: A A Traders | G33: KR | H33: 120 | I33: =IFERROR(IF(D33="Sale",H33*VLOOKUP(G33,Product_Master!$A:$F,6,FALSE()),IF(D33="Purchase",H33*VLOOKUP(G33,Product_Master!$A:$F,5,FALSE()),0)),0) -> 21000
A34: 33 | B34: 46114 | C34: Q1 26-27 | D34: Sale | E34: 73 | F34: Zia Bhai | G34: NSCI | H34: 120 | I34: =IFERROR(IF(D34="Sale",H34*VLOOKUP(G34,Product_Master!$A:$F,6,FALSE()),IF(D34="Purchase",H34*VLOOKUP(G34,Product_Master!$A:$F,5,FALSE()),0)),0) -> 26520
A35: 34 | B35: 46115 | C35: Q1 26-27 | D35: Sale | E35: 16 | F35: Reshmi Leather | G35: SBL | H35: 120 | I35: =IFERROR(IF(D35="Sale",H35*VLOOKUP(G35,Product_Master!$A:$F,6,FALSE()),IF(D35="Purchase",H35*VLOOKUP(G35,Product_Master!$A:$F,5,FALSE()),0)),0) -> 13440
A36: 35 | B36: 46115 | C36: Q1 26-27 | D36: Sale | E36: 17 | F36: Zen International | G36: RU | H36: 240 | I36: =IFERROR(IF(D36="Sale",H36*VLOOKUP(G36,Product_Master!$A:$F,6,FALSE()),IF(D36="Purchase",H36*VLOOKUP(G36,Product_Master!$A:$F,5,FALSE()),0)),0) -> 47520
... A68: 67 | B68: 46118 | C68: Q1 26-27 | D68: Sale | E68: 32 | F68: Aaqib Tannery | G68: SNA | H68: 480 | I68: =IFERROR(IF(D68="Sale",H68*VLOOKUP(G68,Product_Master!$A:$F,6,FALSE()),IF(D68="Purchase",H68*VLOOKUP(G68,Product_Master!$A:$F,5,FALSE()),0)),0) -> 53280
A69: 68 | B69: 46119 | C69: Q1 26-27 | D69: Purchase | F69: ATC | G69: KG | H69: 2200 | I69: =IFERROR(IF(D69="Sale",H69*VLOOKUP(G69,Product_Master!$A:$F,6,FALSE()),IF(D69="Purchase",H69*VLOOKUP(G69,Product_Master!$A:$F,5,FALSE()),0)),0) -> 204600
A70: 69 | B70: 46119 | C70: Q1 26-27 | D70: Purchase | F70: ATC | G70: AA | H70: 2400 | I70: =IFERROR(IF(D70="Sale",H70*VLOOKUP(G70,Product_Master!$A:$F,6,FALSE()),IF(D70="Purchase",H70*VLOOKUP(G70,Product_Master!$A:$F,5,FALSE()),0)),0) -> 230400
A71: 70 | B71: 46119 | C71: Q1 26-27 | D71: Purchase | F71: ATC | G71: WAK | H71: 3600 | I71: =IFERROR(IF(D71="Sale",H71*VLOOKUP(G71,Product_Master!$A:$F,6,FALSE()),IF(D71="Purchase",H71*VLOOKUP(G71,Product_Master!$A:$F,5,FALSE()),0)),0) -> 338400
A72: 71 | B72: 46119 | C72: Q1 26-27 | D72: Purchase | F72: ATC | G72: SNA | H72: 6000 | I72: =IFERROR(IF(D72="Sale",H72*VLOOKUP(G72,Product_Master!$A:$F,6,FALSE()),IF(D72="Purchase",H72*VLOOKUP(G72,Product_Master!$A:$F,5,FALSE()),0)),0) -> 582000
A73: 72 | B73: 46119 | C73: Q1 26-27 | D73: Purchase | F73: ATC | G73: SBL | H73: 2400 | I73: =IFERROR(IF(D73="Sale",H73*VLOOKUP(G73,Product_Master!$A:$F,6,FALSE()),IF(D73="Purchase",H73*VLOOKUP(G73,Product_Master!$A:$F,5,FALSE()),0)),0) -> 237600
A74: 73 | B74: 46119 | C74: Q1 26-27 | D74: Purchase | F74: ATC | G74: XAC | H74: 1200 | I74: =IFERROR(IF(D74="Sale",H74*VLOOKUP(G74,Product_Master!$A:$F,6,FALSE()),IF(D74="Purchase",H74*VLOOKUP(G74,Product_Master!$A:$F,5,FALSE()),0)),0) -> 162000
A75: 74 | B75: 46119 | C75: Q1 26-27 | D75: Purchase | F75: ATC | G75: SBAI | H75: 2500 | I75: =IFERROR(IF(D75="Sale",H75*VLOOKUP(G75,Product_Master!$A:$F,6,FALSE()),IF(D75="Purchase",H75*VLOOKUP(G75,Product_Master!$A:$F,5,FALSE()),0)),0) -> 287500
A76: 75 | B76: 46119 | C76: Q1 26-27 | D76: Purchase | F76: ATC | G76: KI | H76: 240 | I76: =IFERROR(IF(D76="Sale",H76*VLOOKUP(G76,Product_Master!$A:$F,6,FALSE()),IF(D76="Purchase",H76*VLOOKUP(G76,Product_Master!$A:$F,5,FALSE()),0)),0) -> 20400
A77: 76 | B77: 46119 | C77: Q1 26-27 | D77: Sale | E77: 33 | F77: HAMDAAN ENTERPRISE | G77: CRTI | H77: 150 | I77: =IFERROR(IF(D77="Sale",H77*VLOOKUP(G77,Product_Master!$A:$F,6,FALSE()),IF(D77="Purchase",H77*VLOOKUP(G77,Product_Master!$A:$F,5,FALSE()),0)),0) -> 12750
A78: 77 | B78: 46119 | C78: Q1 26-27 | D78: Sale | E78: 34 | F78: Shaheen Traders | G78: CRTI | H78: 250 | I78: =IFERROR(IF(D78="Sale",H78*VLOOKUP(G78,Product_Master!$A:$F,6,FALSE()),IF(D78="Purchase",H78*VLOOKUP(G78,Product_Master!$A:$F,5,FALSE()),0)),0) -> 21250
A79: 78 | B79: 46120 | C79: Q1 26-27 | D79: Sale | E79: 35 | F79: Mariam Fashions Pvt Ltd | G79: WAK | H79: 120 | I79: =IFERROR(IF(D79="Sale",H79*VLOOKUP(G79,Product_Master!$A:$F,6,FALSE()),IF(D79="Purchase",H79*VLOOKUP(G79,Product_Master!$A:$F,5,FALSE()),0)),0) -> 12240
A80: 79 | B80: 46120 | C80: Q1 26-27 | D80: Sale | E80: 35 | F80: Mariam Fashions Pvt Ltd | G80: SNA | H80: 120 | I80: =IFERROR(IF(D80="Sale",H80*VLOOKUP(G80,Product_Master!$A:$F,6,FALSE()),IF(D80="Purchase",H80*VLOOKUP(G80,Product_Master!$A:$F,5,FALSE()),0)),0) -> 13320
...

Sheet Stock_Summary
A1: Product Code | B1: Opening Stock (kg) | C1: Total Purchases (kg) | D1: Total Sales (kg) | E1: Adjustments (kg) | F1: Closing Stock (kg) | G1: Packing Size (kg) | H1: No. of Drums | I1: Purchase Rate (Rs/kg) | J1: Sale Rate (Rs/kg) | K1: Stock Value (Rs) | L1: Sales Value (Rs) | M1: Reorder Level (kg) | N1: Status
A2: =Product_Master!A2 -> KG | B2: =Product_Master!C2 -> 1980 | C2: =SUMIFS(Transactions!$H$2:$H$603,Transactions!$G$2:$G$603,$A2,Transactions!$D$2:$D$603,"Purchase") -> 5280 | D2: =SUMIFS(Transactions!$H$2:$H$603,Transactions!$G$2:$G$603,$A2,Transactions!$D$2:$D$603,"Sale") -> 4130 | E2: =SUMIFS(Transactions!$H$2:$H$603,Transactions!$G$2:$G$603,$A2,Transactions!$D$2:$D$603,"Adjustment") -> 110 | F2: =B2+C2-D2-E2 -> 3020 | G2: =Product_Master!D2 -> 110 | H2: =IF(G2>0,F2/G2,0) -> 27.454545 | I2: =Product_Master!E2 -> 93 | J2: =Product_Master!F2 -> 93 | K2: =IFERROR(F2*I2,0) -> 280860 | L2: =IFERROR(D2*J2,0) -> 384090 | M2: =Product_Master!G2 -> 0 | N2: =IF(AND(M2<>"",F2<M2),"LOW STOCK","OK") -> OK
A3: =Product_Master!A3 -> AA | B3: =Product_Master!C3 -> 973 | C3: =SUMIFS(Transactions!$H$2:$H$603,Transactions!$G$2:$G$603,$A3,Transactions!$D$2:$D$603,"Purchase") -> 4800 | D3: =SUMIFS(Transactions!$H$2:$H$603,Transactions!$G$2:$G$603,$A3,Transactions!$D$2:$D$603,"Sale") -> 2420 | E3: =SUMIFS(Transactions!$H$2:$H$603,Transactions!$G$2:$G$603,$A3,Transactions!$D$2:$D$603,"Adjustment") -> 120 | F3: =B3+C3-D3-E3 -> 3233 | G3: =Product_Master!D3 -> 120 | H3: =IF(G3>0,F3/G3,0) -> 26.941667 | I3: =Product_Master!E3 -> 96 | J3: =Product_Master!F3 -> 106 | K3: =IFERROR(F3*I3,0) -> 310368 | L3: =IFERROR(D3*J3,0) -> 256520 | M3: =Product_Master!G3 -> 0 | N3: =IF(AND(M3<>"",F3<M3),"LOW STOCK","OK") -> OK
A4: =Product_Master!A4 -> WAK | B4: =Product_Master!C4 -> 4713 | C4: =SUMIFS(Transactions!$H$2:$H$603,Transactions!$G$2:$G$603,$A4,Transactions!$D$2:$D$603,"Purchase") -> 10200 | D4: =SUMIFS(Transactions!$H$2:$H$603,Transactions!$G$2:$G$603,$A4,Transactions!$D$2:$D$603,"Sale") -> 9452 | E4: =SUMIFS(Transactions!$H$2:$H$603,Transactions!$G$2:$G$603,$A4,Transactions!$D$2:$D$603,"Adjustment") -> 0 | F4: =B4+C4-D4-E4 -> 5461 | G4: =Product_Master!D4 -> 120 | H4: =IF(G4>0,F4/G4,0) -> 45.508333 | I4: =Product_Master!E4 -> 94 | J4: =Product_Master!F4 -> 102 | K4: =IFERROR(F4*I4,0) -> 513334 | L4: =IFERROR(D4*J4,0) -> 964104 | M4: =Product_Master!G4 -> 0 | N4: =IF(AND(M4<>"",F4<M4),"LOW STOCK","OK") -> OK
A5: =Product_Master!A5 -> SNA | B5: =Product_Master!C5 -> 6707 | C5: =SUMIFS(Transactions!$H$2:$H$603,Transactions!$G$2:$G$603,$A5,Transactions!$D$2:$D$603,"Purchase") -> 21000 | D5: =SUMIFS(Transactions!$H$2:$H$603,Transactions!$G$2:$G$603,$A5,Transactions!$D$2:$D$603,"Sale") -> 19736 | E5: =SUMIFS(Transactions!$H$2:$H$603,Transactions!$G$2:$G$603,$A5,Transactions!$D$2:$D$603,"Adjustment") -> -240 | F5: =B5+C5-D5-E5 -> 8211 | G5: =Product_Master!D5 -> 120 | H5: =IF(G5>0,F5/G5,0) -> 68.425 | I5: =Product_Master!E5 -> 97 | J5: =Product_Master!F5 -> 111 | K5: =IFERROR(F5*I5,0) -> 796467 | L5: =IFERROR(D5*J5,0) -> 2190696 | M5: =Product_Master!G5 -> 0 | N5: =IF(AND(M5<>"",F5<M5),"LOW STOCK","OK") -> OK
A6: =Product_Master!A6 -> SBL | B6: =Product_Master!C6 -> 4800 | C6: =SUMIFS(Transactions!$H$2:$H$603,Transactions!$G$2:$G$603,$A6,Transactions!$D$2:$D$603,"Purchase") -> 28200 | D6: =SUMIFS(Transactions!$H$2:$H$603,Transactions!$G$2:$G$603,$A6,Transactions!$D$2:$D$603,"Sale") -> 24384 | E6: =SUMIFS(Transactions!$H$2:$H$603,Transactions!$G$2:$G$603,$A6,Transactions!$D$2:$D$603,"Adjustment") -> -384 | F6: =B6+C6-D6-E6 -> 9000 | G6: =Product_Master!D6 -> 120 | H6: =IF(G6>0,F6/G6,0) -> 75 | I6: =Product_Master!E6 -> 99 | J6: =Product_Master!F6 -> 112 | K6: =IFERROR(F6*I6,0) -> 891000 | L6: =IFERROR(D6*J6,0) -> 2731008 | M6: =Product_Master!G6 -> 0 | N6: =IF(AND(M6<>"",F6<M6),"LOW STOCK","OK") -> OK
A7: =Product_Master!A7 -> XAC | B7: =Product_Master!C7 -> 310 | C7: =SUMIFS(Transactions!$H$2:$H$603,Transactions!$G$2:$G$603,$A7,Transactions!$D$2:$D$603,"Purchase") -> 3600 | D7: =SUMIFS(Transactions!$H$2:$H$603,Transactions!$G$2:$G$603,$A7,Transactions!$D$2:$D$603,"Sale") -> 2728 | E7: =SUMIFS(Transactions!$H$2:$H$603,Transactions!$G$2:$G$603,$A7,Transactions!$D$2:$D$603,"Adjustment") -> -360 | F7: =B7+C7-D7-E7 -> 1542 | G7: =Product_Master!D7 -> 120 | H7: =IF(G7>0,F7/G7,0) -> 12.85 | I7: =Product_Master!E7 -> 135 | J7: =Product_Master!F7 -> 160 | K7: =IFERROR(F7*I7,0) -> 208170 | L7: =IFERROR(D7*J7,0) -> 436480 | M7: =Product_Master!G7 -> 0 | N7: =IF(AND(M7<>"",F7<M7),"LOW STOCK","OK") -> OK
A8: =Product_Master!A8 -> WFAT | B8: =Product_Master!C8 -> 156 | C8: =SUMIFS(Transactions!$H$2:$H$603,Transactions!$G$2:$G$603,$A8,Transactions!$D$2:$D$603,"Purchase") -> 3480 | D8: =SUMIFS(Transactions!$H$2:$H$603,Transactions!$G$2:$G$603,$A8,Transactions!$D$2:$D$603,"Sale") -> 3308 | E8: =SUMIFS(Transactions!$H$2:$H$603,Transactions!$G$2:$G$603,$A8,Transactions!$D$2:$D$603,"Adjustment") -> 0 | F8: =B8+C8-D8-E8 -> 328 | G8: =Product_Master!D8 -> 120 | H8: =IF(G8>0,F8/G8,0) -> 2.7333333 | I8: =Product_Master!E8 -> 130 | J8: =Product_Master!F8 -> 135 | K8: =IFERROR(F8*I8,0) -> 42640 | L8: =IFERROR(D8*J8,0) -> 446580 | M8: =Product_Master!G8 -> 0 | N8: =IF(AND(M8<>"",F8<M8),"LOW STOCK","OK") -> OK
A9: =Product_Master!A9 -> SUL | B9: =Product_Master!C9 -> 8978 | C9: =SUMIFS(Transactions!$H$2:$H$603,Transactions!$G$2:$G$603,$A9,Transactions!$D$2:$D$603,"Purchase") -> 0 | D9: =SUMIFS(Transactions!$H$2:$H$603,Transactions!$G$2:$G$603,$A9,Transactions!$D$2:$D$603,"Sale") -> 3210 | E9: =SUMIFS(Transactions!$H$2:$H$603,Transactions!$G$2:$G$603,$A9,Transactions!$D$2:$D$603,"Adjustment") -> 0 | F9: =B9+C9-D9-E9 -> 5768 | G9: =Product_Master!D9 -> 150 | H9: =IF(G9>0,F9/G9,0) -> 38.453333 | I9: =Product_Master!E9 -> 148 | J9: =Product_Master!F9 -> 185 | K9: =IFERROR(F9*I9,0) -> 853664 | L9: =IFERROR(D9*J9,0) -> 593850 | M9: =Product_Master!G9 -> 0 | N9: =IF(AND(M9<>"",F9<M9),"LOW STOCK","OK") -> OK
A10: =Product_Master!A10 -> KR | B10: =Product_Master!C10 -> 512 | C10: =SUMIFS(Transactions!$H$2:$H$603,Transactions!$G$2:$G$603,$A10,Transactions!$D$2:$D$603,"Purchase") -> 0 | D10: =SUMIFS(Transactions!$H$2:$H$603,Transactions!$G$2:$G$603,$A10,Transactions!$D$2:$D$603,"Sale") -> 480 | E10: =SUMIFS(Transactions!$H$2:$H$603,Transactions!$G$2:$G$603,$A10,Transactions!$D$2:$D$603,"Adjustment") -> 0 | F10: =B10+C10-D10-E10 -> 32 | G10: =Product_Master!D10 -> 120 | H10: =IF(G10>0,F10/G10,0) -> 0.26666667 | I10: =Product_Master!E10 -> 163 | J10: =Product_Master!F10 -> 175 | K10: =IFERROR(F10*I10,0) -> 5216 | L10: =IFERROR(D10*J10,0) -> 84000 | M10: =Product_Master!G10 -> 0 | N10: =IF(AND(M10<>"",F10<M10),"LOW STOCK","OK") -> OK
A11: =Product_Master!A11 -> G1 | B11: =Product_Master!C11 -> 500 | C11: =SUMIFS(Transactions!$H$2:$H$603,Transactions!$G$2:$G$603,$A11,Transactions!$D$2:$D$603,"Purchase") -> 0 | D11: =SUMIFS(Transactions!$H$2:$H$603,Transactions!$G$2:$G$603,$A11,Transactions!$D$2:$D$603,"Sale") -> 0 | E11: =SUMIFS(Transactions!$H$2:$H$603,Transactions!$G$2:$G$603,$A11,Transactions!$D$2:$D$603,"Adjustment") -> 0 | F11: =B11+C11-D11-E11 -> 500 | G11: =Product_Master!D11 -> 100 | H11: =IF(G11>0,F11/G11,0) -> 5 | I11: =Product_Master!E11 -> 105 | J11: =Product_Master!F11 -> 135 | K11: =IFERROR(F11*I11,0) -> 52500 | L11: =IFERROR(D11*J11,0) -> 0 | M11: =Product_Master!G11 -> 0 | N11: =IF(AND(M11<>"",F11<M11),"LOW STOCK","OK") -> OK
A12: =Product_Master!A12 -> G2 | B12: =Product_Master!C12 -> 100 | C12: =SUMIFS(Transactions!$H$2:$H$603,Transactions!$G$2:$G$603,$A12,Transactions!$D$2:$D$603,"Purchase") -> 0 | D12: =SUMIFS(Transactions!$H$2:$H$603,Transactions!$G$2:$G$603,$A12,Transactions!$D$2:$D$603,"Sale") -> 100 | E12: =SUMIFS(Transactions!$H$2:$H$603,Transactions!$G$2:$G$603,$A12,Transactions!$D$2:$D$603,"Adjustment") -> 0 | F12: =B12+C12-D12-E12 -> 0 | G12: =Product_Master!D12 -> 100 | H12: =IF(G12>0,F12/G12,0) -> 0 | I12: =Product_Master!E12 -> 95 | J12: =Product_Master!F12 -> 130 | K12: =IFERROR(F12*I12,0) -> 0 | L12: =IFERROR(D12*J12,0) -> 13000 | M12: =Product_Master!G12 -> 0 | N12: =IF(AND(M12<>"",F12<M12),"LOW STOCK","OK") -> OK
A13: =Product_Master!A13 -> Silcoat | B13: =Product_Master!C13 -> 590 | C13: =SUMIFS(Transactions!$H$2:$H$603,Transactions!$G$2:$G$603,$A13,Transactions!$D$2:$D$603,"Purchase") -> 2040 | D13: =SUMIFS(Transactions!$H$2:$H$603,Transactions!$G$2:$G$603,$A13,Transactions!$D$2:$D$603,"Sale") -> 2183 | E13: =SUMIFS(Transactions!$H$2:$H$603,Transactions!$G$2:$G$603,$A13,Transactions!$D$2:$D$603,"Adjustment") -> 0 | F13: =B13+C13-D13-E13 -> 447 | G13: =Product_Master!D13 -> 60 | H13: =IF(G13>0,F13/G13,0) -> 7.45 | I13: =Product_Master!E13 -> 45 | J13: =Product_Master!F13 -> 122 | K13: =IFERROR(F13*I13,0) -> 20115 | L13: =IFERROR(D13*J13,0) -> 266326 | M13: =Product_Master!G13 -> 0 | N13: =IF(AND(M13<>"",F13<M13),"LOW STOCK","OK") -> OK
... A56: =Product_Master!A56 -> CWET | B56: =Product_Master!C56 -> 991 | C56: =SUMIFS(Transactions!$H$2:$H$603,Transactions!$G$2:$G$603,$A56,Transactions!$D$2:$D$603,"Purchase") -> 0 | D56: =SUMIFS(Transactions!$H$2:$H$603,Transactions!$G$2:$G$603,$A56,Transactions!$D$2:$D$603,"Sale") -> 74 | E56: =SUMIFS(Transactions!$H$2:$H$603,Transactions!$G$2:$G$603,$A56,Transactions!$D$2:$D$603,"Adjustment") -> 0 | F56: =B56+C56-D56-E56 -> 917 | G56: =Product_Master!D56 -> 50 | H56: =IF(G56>0,F56/G56,0) -> 18.34 | I56: =Product_Master!E56 -> 45 | J56: =Product_Master!F56 -> 245 | K56: =IFERROR(F56*I56,0) -> 41265 | L56: =IFERROR(D56*J56,0) -> 18130 | M56: =Product_Master!G56 -> 0 | N56: =IF(AND(M56<>"",F56<M56),"LOW STOCK","OK") -> OK
A57: TOTAL | B57: =SUM(B2:B56) -> 66590.3 | C57: =SUM(C2:C56) -> 104120 | D57: =SUM(D2:D56) -> 97804.4 | E57: =SUM(E2:E56) -> 162.9 | F57: =SUM(F2:F56) -> 72743 | K57: =SUM(K2:K56) -> 8721679 | L57: =SUM(L2:L56) -> 13028164

Sheet Analysis
B2: Business Efficiency Analysis
B3: All tables below are formulas linked to Product_Master, Stock_Summary and Transactions — add new transactions and this sheet updates automatically.
B4: Note: Sales/Purchase values here are estimates using each product's CURRENT rate in Product_Master (historical per-invoice prices are not stored), so treat Rs figures as indicative, not exact accounting values.
B6: 1. Product Performance — ABC Analysis, Turnover & Margin
P7: Chart data (sorted by rank) — do not edit
B8: Product | C8: Sales Value (Rs) | D8: Sales Rank | E8: Cumulative % | F8: ABC Class | G8: Closing Stock (kg) | H8: Total Sales (kg) | I8: Days Covered | J8: Days of Stock | K8: Turnover Ratio | L8: Margin/kg (Rs) | M8: Total Margin (Rs) | N8: Stock Status | P8: Rank | Q8: Product | R8: Sales Value (Rs) | S8: Cumulative %
B9: =Stock_Summary!A2 -> KG | C9: =Stock_Summary!L2 -> 384090 | D9: =RANK(C9,$C$9:$C$63,0)+COUNTIF($C$9:C9,C9)-1 -> 11 | E9: =SUMIFS($C$9:$C$63,$D$9:$D$63,"<="&D9)/SUM($C$9:$C$63) -> 0.77484735 | F9: =IF(E9<=0.8,"A",IF(E9<=0.95,"B","C")) -> A | G9: =Stock_Summary!F2 -> 3020 | H9: =Stock_Summary!D2 -> 4130 | I9: =MAX(Transactions!$B:$B)-MIN(Transactions!$B:$B)+1 -> 107 | J9: =IF(H9>0,G9*I9/H9,999) -> 78.242131 | K9: =IF((G9+H9)/2>0,H9/((G9+H9)/2),0) -> 1.1552448 | L9: =Stock_Summary!J2-Stock_Summary!I2 -> 0 | M9: =L9*H9 -> 0 | N9: =IF(AND(H9=0,G9>0),"DEAD STOCK",IF(J9>180,"SLOW MOVING","OK")) -> OK | P9: 1 | Q9: =INDEX($B$9:$B$63,MATCH(P9,$D$9:$D$63,0)) -> SBL | R9: =INDEX($C$9:$C$63,MATCH(P9,$D$9:$D$63,0)) -> 2731008 | S9: =INDEX($E$9:$E$63,MATCH(P9,$D$9:$D$63,0)) -> 0.2096234
B10: =Stock_Summary!A3 -> AA | C10: =Stock_Summary!L3 -> 256520 | D10: =RANK(C10,$C$9:$C$63,0)+COUNTIF($C$9:C10,C10)-1 -> 16 | E10: =SUMIFS($C$9:$C$63,$D$9:$D$63,"<="&D10)/SUM($C$9:$C$63) -> 0.87972867 | F10: =IF(E10<=0.8,"A",IF(E10<=0.95,"B","C")) -> B | G10: =Stock_Summary!F3 -> 3233 | H10: =Stock_Summary!D3 -> 2420 | I10: =MAX(Transactions!$B:$B)-MIN(Transactions!$B:$B)+1 -> 107 | J10: =IF(H10>0,G10*I10/H10,999) -> 142.94669 | K10: =IF((G10+H10)/2>0,H10/((G10+H10)/2),0) -> 0.85618256 | L10: =Stock_Summary!J3-Stock_Summary!I3 -> 10 | M10: =L10*H10 -> 24200 | N10: =IF(AND(H10=0,G10>0),"DEAD STOCK",IF(J10>180,"SLOW MOVING","OK")) -> OK | P10: 2 | Q10: =INDEX($B$9:$B$63,MATCH(P10,$D$9:$D$63,0)) -> SNA | R10: =INDEX($C$9:$C$63,MATCH(P10,$D$9:$D$63,0)) -> 2190696 | S10: =INDEX($E$9:$E$63,MATCH(P10,$D$9:$D$63,0)) -> 0.37777419
B11: =Stock_Summary!A4 -> WAK | C11: =Stock_Summary!L4 -> 964104 | D11: =RANK(C11,$C$9:$C$63,0)+COUNTIF($C$9:C11,C11)-1 -> 3 | E11: =SUMIFS($C$9:$C$63,$D$9:$D$63,"<="&D11)/SUM($C$9:$C$63) -> 0.45177572 | F11: =IF(E11<=0.8,"A",IF(E11<=0.95,"B","C")) -> A | G11: =Stock_Summary!F4 -> 5461 | H11: =Stock_Summary!D4 -> 9452 | I11: =MAX(Transactions!$B:$B)-MIN(Transactions!$B:$B)+1 -> 107 | J11: =IF(H11>0,G11*I11/H11,999) -> 61.820461 | K11: =IF((G11+H11)/2>0,H11/((G11+H11)/2),0) -> 1.2676189 | L11: =Stock_Summary!J4-Stock_Summary!I4 -> 8 | M11: =L11*H11 -> 75616 | N11: =IF(AND(H11=0,G11>0),"DEAD STOCK",IF(J11>180,"SLOW MOVING","OK")) -> OK | P11: 3 | Q11: =INDEX($B$9:$B$63,MATCH(P11,$D$9:$D$63,0)) -> WAK | R11: =INDEX($C$9:$C$63,MATCH(P11,$D$9:$D$63,0)) -> 964104 | S11: =INDEX($E$9:$E$63,MATCH(P11,$D$9:$D$63,0)) -> 0.45177572
B12: =Stock_Summary!A5 -> SNA | C12: =Stock_Summary!L5 -> 2190696 | D12: =RANK(C12,$C$9:$C$63,0)+COUNTIF($C$9:C12,C12)-1 -> 2 | E12: =SUMIFS($C$9:$C$63,$D$9:$D$63,"<="&D12)/SUM($C$9:$C$63) -> 0.37777419 | F12: =IF(E12<=0.8,"A",IF(E12<=0.95,"B","C")) -> A | G12: =Stock_Summary!F5 -> 8211 | H12: =Stock_Summary!D5 -> 19736 | I12: =MAX(Transactions!$B:$B)-MIN(Transactions!$B:$B)+1 -> 107 | J12: =IF(H12>0,G12*I12/H12,999) -> 44.516467 | K12: =IF((G12+H12)/2>0,H12/((G12+H12)/2),0) -> 1.4123877 | L12: =Stock_Summary!J5-Stock_Summary!I5 -> 14 | M12: =L12*H12 -> 276304 | N12: =IF(AND(H12=0,G12>0),"DEAD STOCK",IF(J12>180,"SLOW MOVING","OK")) -> OK | P12: 4 | Q12: =INDEX($B$9:$B$63,MATCH(P12,$D$9:$D$63,0)) -> TiO2 | R12: =INDEX($C$9:$C$63,MATCH(P12,$D$9:$D$63,0)) -> 748125 | S12: =INDEX($E$9:$E$63,MATCH(P12,$D$9:$D$63,0)) -> 0.50919939
B13: =Stock_Summary!A6 -> SBL | C13: =Stock_Summary!L6 -> 2731008 | D13: =RANK(C13,$C$9:$C$63,0)+COUNTIF($C$9:C13,C13)-1 -> 1 | E13: =SUMIFS($C$9:$C$63,$D$9:$D$63,"<="&D13)/SUM($C$9:$C$63) -> 0.2096234 | F13: =IF(E13<=0.8,"A",IF(E13<=0.95,"B","C")) -> A | G13: =Stock_Summary!F6 -> 9000 | H13: =Stock_Summary!D6 -> 24384 | I13: =MAX(Transactions!$B:$B)-MIN(Transactions!$B:$B)+1 -> 107 | J13: =IF(H13>0,G13*I13/H13,999) -> 39.49311 | K13: =IF((G13+H13)/2>0,H13/((G13+H13)/2),0) -> 1.4608196 | L13: =Stock_Summary!J6-Stock_Summary!I6 -> 13 | M13: =L13*H13 -> 316992 | N13: =IF(AND(H13=0,G13>0),"DEAD STOCK",IF(J13>180,"SLOW MOVING","OK")) -> OK | P13: 5 | Q13: =INDEX($B$9:$B$63,MATCH(P13,$D$9:$D$63,0)) -> SUL | R13: =INDEX($C$9:$C$63,MATCH(P13,$D$9:$D$63,0)) -> 593850 | S13: =INDEX($E$9:$E$63,MATCH(P13,$D$9:$D$63,0)) -> 0.55478141
B14: =Stock_Summary!A7 -> XAC | C14: =Stock_Summary!L7 -> 436480 | D14: =RANK(C14,$C$9:$C$63,0)+COUNTIF($C$9:C14,C14)-1 -> 9 | E14: =SUMIFS($C$9:$C$63,$D$9:$D$63,"<="&D14)/SUM($C$9:$C$63) -> 0.71253849 | F14: =IF(E14<=0.8,"A",IF(E14<=0.95,"B","C")) -> A | G14: =Stock_Summary!F7 -> 1542 | H14: =Stock_Summary!D7 -> 2728 | I14: =MAX(Transactions!$B:$B)-MIN(Transactions!$B:$B)+1 -> 107 | J14: =IF(H14>0,G14*I14/H14,999) -> 60.481672 | K14: =IF((G14+H14)/2>0,H14/((G14+H14)/2),0) -> 1.2777518 | L14: =Stock_Summary!J7-Stock_Summary!I7 -> 25 | M14: =L14*H14 -> 68200 | N14: =IF(AND(H14=0,G14>0),"DEAD STOCK",IF(J14>180,"SLOW MOVING","OK")) -> OK | P14: 6 | Q14: =INDEX($B$9:$B$63,MATCH(P14,$D$9:$D$63,0)) -> XNB 900 | R14: =INDEX($C$9:$C$63,MATCH(P14,$D$9:$D$63,0)) -> 588600 | S14: =INDEX($E$9:$E$63,MATCH(P14,$D$9:$D$63,0)) -> 0.59996046
B15: =Stock_Summary!A8 -> WFAT | C15: =Stock_Summary!L8 -> 446580 | D15: =RANK(C15,$C$9:$C$63,0)+COUNTIF($C$9:C15,C15)-1 -> 8 | E15: =SUMIFS($C$9:$C$63,$D$9:$D$63,"<="&D15)/SUM($C$9:$C$63) -> 0.67903569 | F15: =IF(E15<=0.8,"A",IF(E15<=0.95,"B","C")) -> A | G15: =Stock_Summary!F8 -> 328 | H15: =Stock_Summary!D8 -> 3308 | I15: =MAX(Transactions!$B:$B)-MIN(Transactions!$B:$B)+1 -> 107 | J15: =IF(H15>0,G15*I15/H15,999) -> 10.609432 | K15: =IF((G15+H15)/2>0,H15/((G15+H15)/2),0) -> 1.819582 | L15: =Stock_Summary!J8-Stock_Summary!I8 -> 5 | M15: =L15*H15 -> 16540 | N15: =IF(AND(H15=0,G15>0),"DEAD STOCK",IF(J15>180,"SLOW MOVING","OK")) -> OK | P15: 7 | Q15: =INDEX($B$9:$B$63,MATCH(P15,$D$9:$D$63,0)) -> AW | R15: =INDEX($C$9:$C$63,MATCH(P15,$D$9:$D$63,0)) -> 583625 | S15: =INDEX($E$9:$E$63,MATCH(P15,$D$9:$D$63,0)) -> 0.64475764
B16: =Stock_Summary!A9 -> SUL | C16: =Stock_Summary!L9 -> 593850 | D16: =RANK(C16,$C$9:$C$63,0)+COUNTIF($C$9:C16,C16)-1 -> 5 | E16: =SUMIFS($C$9:$C$63,$D$9:$D$63,"<="&D16)/SUM($C$9:$C$63) -> 0.55478141 | F16: =IF(E16<=0.8,"A",IF(E16<=0.95,"B","C")) -> A | G16: =Stock_Summary!F9 -> 5768 | H16: =Stock_Summary!D9 -> 3210 | I16: =MAX(Transactions!$B:$B)-MIN(Transactions!$B:$B)+1 -> 107 | J16: =IF(H16>0,G16*I16/H16,999) -> 192.26667 | K16: =IF((G16+H16)/2>0,H16/((G16+H16)/2),0) -> 0.71508131 | L16: =Stock_Summary!J9-Stock_Summary!I9 -> 37 | M16: =L16*H16 -> 118770 | N16: =IF(AND(H16=0,G16>0),"DEAD STOCK",IF(J16>180,"SLOW MOVING","OK")) -> SLOW MOVING | P16: 8 | Q16: =INDEX($B$9:$B$63,MATCH(P16,$D$9:$D$63,0)) -> WFAT | R16: =INDEX($C$9:$C$63,MATCH(P16,$D$9:$D$63,0)) -> 446580 | S16: =INDEX($E$9:$E$63,MATCH(P16,$D$9:$D$63,0)) -> 0.67903569
B17: =Stock_Summary!A10 -> KR | C17: =Stock_Summary!L10 -> 84000 | D17: =RANK(C17,$C$9:$C$63,0)+COUNTIF($C$9:C17,C17)-1 -> 24 | E17: =SUMIFS($C$9:$C$63,$D$9:$D$63,"<="&D17)/SUM($C$9:$C$63) -> 0.97345413 | F17: =IF(E17<=0.8,"A",IF(E17<=0.95,"B","C")) -> C | G17: =Stock_Summary!F10 -> 32 | H17: =Stock_Summary!D10 -> 480 | I17: =MAX(Transactions!$B:$B)-MIN(Transactions!$B:$B)+1 -> 107 | J17: =IF(H17>0,G17*I17/H17,999) -> 7.1333333 | K17: =IF((G17+H17)/2>0,H17/((G17+H17)/2),0) -> 1.875 | L17: =Stock_Summary!J10-Stock_Summary!I10 -> 12 | M17: =L17*H17 -> 5760 | N17: =IF(AND(H17=0,G17>0),"DEAD STOCK",IF(J17>180,"SLOW MOVING","OK")) -> OK | P17: 9 | Q17: =INDEX($B$9:$B$63,MATCH(P17,$D$9:$D$63,0)) -> XAC | R17: =INDEX($C$9:$C$63,MATCH(P17,$D$9:$D$63,0)) -> 436480 | S17: =INDEX($E$9:$E$63,MATCH(P17,$D$9:$D$63,0)) -> 0.71253849
B18: =Stock_Summary!A11 -> G1 | C18: =Stock_Summary!L11 -> 0 | D18: =RANK(C18,$C$9:$C$63,0)+COUNTIF($C$9:C18,C18)-1 -> 37 | E18: =SUMIFS($C$9:$C$63,$D$9:$D$63,"<="&D18)/SUM($C$9:$C$63) -> 1 | F18: =IF(E18<=0.8,"A",IF(E18<=0.95,"B","C")) -> C | G18: =Stock_Summary!F11 -> 500 | H18: =Stock_Summary!D11 -> 0 | I18: =MAX(Transactions!$B:$B)-MIN(Transactions!$B:$B)+1 -> 107 | J18: =IF(H18>0,G18*I18/H18,999) -> 999 | K18: =IF((G18+H18)/2>0,H18/((G18+H18)/2),0) -> 0 | L18: =Stock_Summary!J11-Stock_Summary!I11 -> 30 | M18: =L18*H18 -> 0 | N18: =IF(AND(H18=0,G18>0),"DEAD STOCK",IF(J18>180,"SLOW MOVING","OK")) -> DEAD STOCK | P18: 10 | Q18: =INDEX($B$9:$B$63,MATCH(P18,$D$9:$D$63,0)) -> RU | R18: =INDEX($C$9:$C$63,MATCH(P18,$D$9:$D$63,0)) -> 427680 | S18: =INDEX($E$9:$E$63,MATCH(P18,$D$9:$D$63,0)) -> 0.74536583
B19: =Stock_Summary!A12 -> G2 | C19: =Stock_Summary!L12 -> 13000 | D19: =RANK(C19,$C$9:$C$63,0)+COUNTIF($C$9:C19,C19)-1 -> 33 | E19: =SUMIFS($C$9:$C$63,$D$9:$D$63,"<="&D19)/SUM($C$9:$C$63) -> 0.9995499 | F19: =IF(E19<=0.8,"A",IF(E19<=0.95,"B","C")) -> C | G19: =Stock_Summary!F12 -> 0 | H19: =Stock_Summary!D12 -> 100 | I19: =MAX(Transactions!$B:$B)-MIN(Transactions!$B:$B)+1 -> 107 | J19: =IF(H19>0,G19*I19/H19,999) -> 0 | K19: =IF((G19+H19)/2>0,H19/((G19+H19)/2),0) -> 2 | L19: =Stock_Summary!J12-Stock_Summary!I12 -> 35 | M19: =L19*H19 -> 3500 | N19: =IF(AND(H19=0,G19>0),"DEAD STOCK",IF(J19>180,"SLOW MOVING","OK")) -> OK | P19: 11 | Q19: =INDEX($B$9:$B$63,MATCH(P19,$D$9:$D$63,0)) -> KG | R19: =INDEX($C$9:$C$63,MATCH(P19,$D$9:$D$63,0)) -> 384090 | S19: =INDEX($E$9:$E$63,MATCH(P19,$D$9:$D$63,0)) -> 0.77484735
B20: =Stock_Summary!A13 -> Silcoat | C20: =Stock_Summary!L13 -> 266326 | D20: =RANK(C20,$C$9:$C$63,0)+COUNTIF($C$9:C20,C20)-1 -> 14 | E20: =SUMIFS($C$9:$C$63,$D$9:$D$63,"<="&D20)/SUM($C$9:$C$63) -> 0.84030101 | F20: =IF(E20<=0.8,"A",IF(E20<=0.95,"B","C")) -> B | G20: =Stock_Summary!F13 -> 447 | H20: =Stock_Summary!D13 -> 2183 | I20: =MAX(Transactions!$B:$B)-MIN(Transactions!$B:$B)+1 -> 107 | J20: =IF(H20>0,G20*I20/H20,999) -> 21.909757 | K20: =IF((G20+H20)/2>0,H20/((G20+H20)/2),0) -> 1.660076 | L20: =Stock_Summary!J13-Stock_Summary!I13 -> 77 | M20: =L20*H20 -> 168091 | N20: =IF(AND(H20=0,G20>0),"DEAD STOCK",IF(J20>180,"SLOW MOVING","OK")) -> OK | P20: 12 | Q20: =INDEX($B$9:$B$63,MATCH(P20,$D$9:$D$63,0)) -> CRTI | R20: =INDEX($C$9:$C$63,MATCH(P20,$D$9:$D$63,0)) -> 297500 | S20: =INDEX($E$9:$E$63,MATCH(P20,$D$9:$D$63,0)) -> 0.79768249
... B63: =Stock_Summary!A56 -> CWET | C63: =Stock_Summary!L56 -> 18130 | D63: =RANK(C63,$C$9:$C$63,0)+COUNTIF($C$9:C63,C63)-1 -> 31 | E63: =SUMIFS($C$9:$C$63,$D$9:$D$63,"<="&D63)/SUM($C$9:$C$63) -> 0.99717044 | F63: =IF(E63<=0.8,"A",IF(E63<=0.95,"B","C")) -> C | G63: =Stock_Summary!F56 -> 917 | H63: =Stock_Summary!D56 -> 74 | I63: =MAX(Transactions!$B:$B)-MIN(Transactions!$B:$B)+1 -> 107 | J63: =IF(H63>0,G63*I63/H63,999) -> 1325.9324 | K63: =IF((G63+H63)/2>0,H63/((G63+H63)/2),0) -> 0.1493441 | L63: =Stock_Summary!J56-Stock_Summary!I56 -> 200 | M63: =L63*H63 -> 14800 | N63: =IF(AND(H63=0,G63>0),"DEAD STOCK",IF(J63>180,"SLOW MOVING","OK")) -> SLOW MOVING | P63: 55 | Q63: =INDEX($B$9:$B$63,MATCH(P63,$D$9:$D$63,0)) -> KI | R63: =INDEX($C$9:$C$63,MATCH(P63,$D$9:$D$63,0)) -> 0 | S63: =INDEX($E$9:$E$63,MATCH(P63,$D$9:$D$63,0)) -> 1
B66: 2. Customer Concentration (Sales)
H67: Chart data — top customers by value (do not edit)
B68: Customer | C68: Total Sales Qty (kg) | D68: Est. Sales Value (Rs) | E68: % of Total Sales Value | F68: Rank | H68: Rank | I68: Customer | J68: Est. Sales Value (Rs)
B69: A A Traders | C69: =SUMIFS(Transactions!$H$2:$H$603,Transactions!$F$2:$F$603,B69,Transactions!$D$2:$D$603,"Sale") -> 480 | D69: =SUMIFS(Transactions!$I$2:$I$603,Transactions!$F$2:$F$603,B69,Transactions!$D$2:$D$603,"Sale") -> 71520 | E69: =IF(SUM($D$69:$D$164)>0,D69/SUM($D$69:$D$164),0) -> 0.0050216278 | F69: =RANK(D69,$D$69:$D$164,0)+COUNTIF($D$69:D69,D69)-1 -> 42 | H69: 1 | I69: =INDEX($B$69:$B$164,MATCH(H69,$F$69:$F$164,0)) -> Labbaik International | J69: =INDEX($D$69:$D$164,MATCH(H69,$F$69:$F$164,0)) -> 950640
B70: A H Enterprise | C70: =SUMIFS(Transactions!$H$2:$H$603,Transactions!$F$2:$F$603,B70,Transactions!$D$2:$D$603,"Sale") -> 1685 | D70: =SUMIFS(Transactions!$I$2:$I$603,Transactions!$F$2:$F$603,B70,Transactions!$D$2:$D$603,"Sale") -> 205375 | E70: =IF(SUM($D$69:$D$164)>0,D70/SUM($D$69:$D$164),0) -> 0.014419978 | F70: =RANK(D70,$D$69:$D$164,0)+COUNTIF($D$69:D70,D70)-1 -> 18 | H70: 2 | I70: =INDEX($B$69:$B$164,MATCH(H70,$F$69:$F$164,0)) -> TIGER INTERNATIONAL | J70: =INDEX($D$69:$D$164,MATCH(H70,$F$69:$F$164,0)) -> 944680
B71: A Z Enterprise | C71: =SUMIFS(Transactions!$H$2:$H$603,Transactions!$F$2:$F$603,B71,Transactions!$D$2:$D$603,"Sale") -> 6690 | D71: =SUMIFS(Transactions!$I$2:$I$603,Transactions!$F$2:$F$603,B71,Transactions!$D$2:$D$603,"Sale") -> 924690 | E71: =IF(SUM($D$69:$D$164)>0,D71/SUM($D$69:$D$164),0) -> 0.064925182 | F71: =RANK(D71,$D$69:$D$164,0)+COUNTIF($D$69:D71,D71)-1 -> 4 | H71: 3 | I71: =INDEX($B$69:$B$164,MATCH(H71,$F$69:$F$164,0)) -> Tiger International | J71: =INDEX($D$69:$D$164,MATCH(H71,$F$69:$F$164,0)) -> 944680
B72: AH Tiam Tannery | C72: =SUMIFS(Transactions!$H$2:$H$603,Transactions!$F$2:$F$603,B72,Transactions!$D$2:$D$603,"Sale") -> 380 | D72: =SUMIFS(Transactions!$I$2:$I$603,Transactions!$F$2:$F$603,B72,Transactions!$D$2:$D$603,"Sale") -> 85850 | E72: =IF(SUM($D$69:$D$164)>0,D72/SUM($D$69:$D$164),0) -> 0.0060277789 | F72: =RANK(D72,$D$69:$D$164,0)+COUNTIF($D$69:D72,D72)-1 -> 40 | H72: 4 | I72: =INDEX($B$69:$B$164,MATCH(H72,$F$69:$F$164,0)) -> A Z Enterprise | J72: =INDEX($D$69:$D$164,MATCH(H72,$F$69:$F$164,0)) -> 924690
B73: AMS INTERNATIONAL | C73: =SUMIFS(Transactions!$H$2:$H$603,Transactions!$F$2:$F$603,B73,Transactions!$D$2:$D$603,"Sale") -> 1200 | D73: =SUMIFS(Transactions!$I$2:$I$603,Transactions!$F$2:$F$603,B73,Transactions!$D$2:$D$603,"Sale") -> 124800 | E73: =IF(SUM($D$69:$D$164)>0,D73/SUM($D$69:$D$164),0) -> 0.008762572 | F73: =RANK(D73,$D$69:$D$164,0)+COUNTIF($D$69:D73,D73)-1 -> 30 | H73: 5 | I73: =INDEX($B$69:$B$164,MATCH(H73,$F$69:$F$164,0)) -> HAMDAAN ENTERPRISE | J73: =INDEX($D$69:$D$164,MATCH(H73,$F$69:$F$164,0)) -> 861710
B74: AMS International | C74: =SUMIFS(Transactions!$H$2:$H$603,Transactions!$F$2:$F$603,B74,Transactions!$D$2:$D$603,"Sale") -> 1200 | D74: =SUMIFS(Transactions!$I$2:$I$603,Transactions!$F$2:$F$603,B74,Transactions!$D$2:$D$603,"Sale") -> 124800 | E74: =IF(SUM($D$69:$D$164)>0,D74/SUM($D$69:$D$164),0) -> 0.008762572 | F74: =RANK(D74,$D$69:$D$164,0)+COUNTIF($D$69:D74,D74)-1 -> 31 | H74: 6 | I74: =INDEX($B$69:$B$164,MATCH(H74,$F$69:$F$164,0)) -> Dilshad Ahmed & Co | J74: =INDEX($D$69:$D$164,MATCH(H74,$F$69:$F$164,0)) -> 769440
B75: Aaqib Tannery | C75: =SUMIFS(Transactions!$H$2:$H$603,Transactions!$F$2:$F$603,B75,Transactions!$D$2:$D$603,"Sale") -> 2000 | D75: =SUMIFS(Transactions!$I$2:$I$603,Transactions!$F$2:$F$603,B75,Transactions!$D$2:$D$603,"Sale") -> 201200 | E75: =IF(SUM($D$69:$D$164)>0,D75/SUM($D$69:$D$164),0) -> 0.014126839 | F75: =RANK(D75,$D$69:$D$164,0)+COUNTIF($D$69:D75,D75)-1 -> 19 | H75: 7 | I75: =INDEX($B$69:$B$164,MATCH(H75,$F$69:$F$164,0)) -> New Horizons Pvt Ltd | J75: =INDEX($D$69:$D$164,MATCH(H75,$F$69:$F$164,0)) -> 674430
B76: Abdin | C76: =SUMIFS(Transactions!$H$2:$H$603,Transactions!$F$2:$F$603,B76,Transactions!$D$2:$D$603,"Sale") -> 170 | D76: =SUMIFS(Transactions!$I$2:$I$603,Transactions!$F$2:$F$603,B76,Transactions!$D$2:$D$603,"Sale") -> 27150 | E76: =IF(SUM($D$69:$D$164)>0,D76/SUM($D$69:$D$164),0) -> 0.0019062807 | F76: =RANK(D76,$D$69:$D$164,0)+COUNTIF($D$69:D76,D76)-1 -> 62 | H76: 8 | I76: =INDEX($B$69:$B$164,MATCH(H76,$F$69:$F$164,0)) -> New Horizons Pvt. Ltd | J76: =INDEX($D$69:$D$164,MATCH(H76,$F$69:$F$164,0)) -> 541950
B77: Abdin Leather Conceria Pvt.Ltd | C77: =SUMIFS(Transactions!$H$2:$H$603,Transactions!$F$2:$F$603,B77,Transactions!$D$2:$D$603,"Sale") -> 2367 | D77: =SUMIFS(Transactions!$I$2:$I$603,Transactions!$F$2:$F$603,B77,Transactions!$D$2:$D$603,"Sale") -> 373984 | E77: =IF(SUM($D$69:$D$164)>0,D77/SUM($D$69:$D$164),0) -> 0.026258508 | F77: =RANK(D77,$D$69:$D$164,0)+COUNTIF($D$69:D77,D77)-1 -> 10 | H77: 9 | I77: =INDEX($B$69:$B$164,MATCH(H77,$F$69:$F$164,0)) -> Globus Alexium | J77: =INDEX($D$69:$D$164,MATCH(H77,$F$69:$F$164,0)) -> 527800
B78: Aqsa International | C78: =SUMIFS(Transactions!$H$2:$H$603,Transactions!$F$2:$F$603,B78,Transactions!$D$2:$D$603,"Sale") -> 120 | D78: =SUMIFS(Transactions!$I$2:$I$603,Transactions!$F$2:$F$603,B78,Transactions!$D$2:$D$603,"Sale") -> 13440 | E78: =IF(SUM($D$69:$D$164)>0,D78/SUM($D$69:$D$164),0) -> 0.0009436616 | F78: =RANK(D78,$D$69:$D$164,0)+COUNTIF($D$69:D78,D78)-1 -> 79 | H78: 10 | I78: =INDEX($B$69:$B$164,MATCH(H78,$F$69:$F$164,0)) -> Abdin Leather Conceria Pvt.Ltd | J78: =INDEX($D$69:$D$164,MATCH(H78,$F$69:$F$164,0)) -> 373984
B79: Arihant International | C79: =SUMIFS(Transactions!$H$2:$H$603,Transactions!$F$2:$F$603,B79,Transactions!$D$2:$D$603,"Sale") -> 1440 | D79: =SUMIFS(Transactions!$I$2:$I$603,Transactions!$F$2:$F$603,B79,Transactions!$D$2:$D$603,"Sale") -> 183840 | E79: =IF(SUM($D$69:$D$164)>0,D79/SUM($D$69:$D$164),0) -> 0.012907943 | F79: =RANK(D79,$D$69:$D$164,0)+COUNTIF($D$69:D79,D79)-1 -> 22 | H79: 11 | I79: =INDEX($B$69:$B$164,MATCH(H79,$F$69:$F$164,0)) -> Umar Traders | J79: =INDEX($D$69:$D$164,MATCH(H79,$F$69:$F$164,0)) -> 304080
B80: Ashraf Tannery | C80: =SUMIFS(Transactions!$H$2:$H$603,Transactions!$F$2:$F$603,B80,Transactions!$D$2:$D$603,"Sale") -> 120 | D80: =SUMIFS(Transactions!$I$2:$I$603,Transactions!$F$2:$F$603,B80,Transactions!$D$2:$D$603,"Sale") -> 19200 | E80: =IF(SUM($D$69:$D$164)>0,D80/SUM($D$69:$D$164),0) -> 0.001348088 | F80: =RANK(D80,$D$69:$D$164,0)+COUNTIF($D$69:D80,D80)-1 -> 74 | H80: 12 | I80: =INDEX($B$69:$B$164,MATCH(H80,$F$69:$F$164,0)) -> Chen Kuo Jung | J80: =INDEX($D$69:$D$164,MATCH(H80,$F$69:$F$164,0)) -> 297000
... B83: Chen Kuo Jung | C83: =SUMIFS(Transactions!$H$2:$H$603,Transactions!$F$2:$F$603,B83,Transactions!$D$2:$D$603,"Sale") -> 1100 | D83: =SUMIFS(Transactions!$I$2:$I$603,Transactions!$F$2:$F$603,B83,Transactions!$D$2:$D$603,"Sale") -> 297000 | E83: =IF(SUM($D$69:$D$164)>0,D83/SUM($D$69:$D$164),0) -> 0.020853236 | F83: =RANK(D83,$D$69:$D$164,0)+COUNTIF($D$69:D83,D83)-1 -> 12 | H83: 15 | I83: =INDEX($B$69:$B$164,MATCH(H83,$F$69:$F$164,0)) -> Rahaman Industries | J83: =INDEX($D$69:$D$164,MATCH(H83,$F$69:$F$164,0)) -> 273080
B84: Chieh Shing Tannery | C84: =SUMIFS(Transactions!$H$2:$H$603,Transactions!$F$2:$F$603,B84,Transactions!$D$2:$D$603,"Sale") -> 450 | D84: =SUMIFS(Transactions!$I$2:$I$603,Transactions!$F$2:$F$603,B84,Transactions!$D$2:$D$603,"Sale") -> 65000 | E84: =IF(SUM($D$69:$D$164)>0,D84/SUM($D$69:$D$164),0) -> 0.0045638396 | F84: =RANK(D84,$D$69:$D$164,0)+COUNTIF($D$69:D84,D84)-1 -> 45
B85: Classic Leather | C85: =SUMIFS(Transactions!$H$2:$H$603,Transactions!$F$2:$F$603,B85,Transactions!$D$2:$D$603,"Sale") -> 20 | D85: =SUMIFS(Transactions!$I$2:$I$603,Transactions!$F$2:$F$603,B85,Transactions!$D$2:$D$603,"Sale") -> 18000 | E85: =IF(SUM($D$69:$D$164)>0,D85/SUM($D$69:$D$164),0) -> 0.0012638325 | F85: =RANK(D85,$D$69:$D$164,0)+COUNTIF($D$69:D85,D85)-1 -> 77 | H85: Segment | I85: Est. Sales Value (Rs)
B86: Dayanidhi Textiles Pvt. Ltd | C86: =SUMIFS(Transactions!$H$2:$H$603,Transactions!$F$2:$F$603,B86,Transactions!$D$2:$D$603,"Sale") -> 240 | D86: =SUMIFS(Transactions!$I$2:$I$603,Transactions!$F$2:$F$603,B86,Transactions!$D$2:$D$603,"Sale") -> 47520 | E86: =IF(SUM($D$69:$D$164)>0,D86/SUM($D$69:$D$164),0) -> 0.0033365178 | F86: =RANK(D86,$D$69:$D$164,0)+COUNTIF($D$69:D86,D86)-1 -> 56 | H86: Top 5 Customers | I86: =SUM(J69:J73) -> 4626400
B87: Dilshad Ahmed & Co | C87: =SUMIFS(Transactions!$H$2:$H$603,Transactions!$F$2:$F$603,B87,Transactions!$D$2:$D$603,"Sale") -> 7120 | D87: =SUMIFS(Transactions!$I$2:$I$603,Transactions!$F$2:$F$603,B87,Transactions!$D$2:$D$603,"Sale") -> 769440 | E87: =IF(SUM($D$69:$D$164)>0,D87/SUM($D$69:$D$164),0) -> 0.054024627 | F87: =RANK(D87,$D$69:$D$164,0)+COUNTIF($D$69:D87,D87)-1 -> 6 | H87: All Other Customers | I87: =SUM($D$69:$D$164)-I86 -> 9615993.6
B88: Dilshad Ahmed & Co. | C88: =SUMIFS(Transactions!$H$2:$H$603,Transactions!$F$2:$F$603,B88,Transactions!$D$2:$D$603,"Sale") -> 1600 | D88: =SUMIFS(Transactions!$I$2:$I$603,Transactions!$F$2:$F$603,B88,Transactions!$D$2:$D$603,"Sale") -> 169000 | E88: =IF(SUM($D$69:$D$164)>0,D88/SUM($D$69:$D$164),0) -> 0.011865983 | F88: =RANK(D88,$D$69:$D$164,0)+COUNTIF($D$69:D88,D88)-1 -> 23
...
